---
layout: post
title: '大前端之路'
subtitle: 'Promise入门到蒙圈'
date: 2018-12-20
categories: 技术
cover: 'https://zhaoyanda-blog.oss-cn-qingdao.aliyuncs.com/%E5%8D%9A%E5%AE%A2%E5%B0%81%E9%9D%A2/Promise.jpg'
tags: JavaScript
---

### 什么是Promise?

`Promise`可以看成处理异步编程一种解决方案, 在ES6中被写进语言标准, 也就是说原生提供`Promise`对象.

`Promise`有两个特点:

- `Promise`有三种状态 `pending` `fulfilled` `rejected`, 分别代表着进行中, 已完成和失败, `Promise`的状态不受外部影响, `Promise`代表着一个异步操作, 只有这个异步操作的结果能够改变`Promise`对象的状态.

- 状态只能改变一次, 状态更改只有两种, `pending` -> `fulfilled` 和 `pending` -> `rejected`, 也就是说, 状态更改后, 再对`Promise`对象添加回调函数, 会立即得到这个结果.

`Promise`对象可以把异步的操作以同步的形式表达出来, 且提供统一接口, 使异步操作更容易控制.

当然`Promise`也有缺点, `Promise`是无法取消的, 且若不设置对应的回调函数, 内部抛出的异常外部是无法感知的.

## 基本用法

首先用`Promise`构造函数生成一个实例.

<pre><code class="language-javascript">const promise = new Promise((resolve, reject) => {
	if (/*异步结果是否成功*/) {
		resolve(res);
	}else {
		reject(error);
	}
});
</code></pre>
`Promise`构造函数接受一个函数作为参数, 传入函数的内容也就是要执行的异步操作, 构造函数调用传入的函数时, 会给传入函数传入两个参数, 分别是`resolve`和`reject`, 这两个参数是由JS引擎提供.

调用`resolve`和`reject`函数可以改变`Promise`对象的状态(Promise对象内部抛出异常也会改变Promise对象状态).如上文所说, `Promise`实例是有状态的, 他们的作用如下:

- `resolve`: 状态由 `pending` 改变为 `fulfilled`, 将操作结果作为参数传递出去.
- `rejected`: 状态由 `pending` 改变为 `rejected`, 将异常作为参数传递出去.


获取`resolved`状态和`rejected`状态回调

<pre><code class="language-javascript">promise.then((res) => {
	// success
	console.log(res)
}, (error) => {
	// failure
});
</code></pre>
`then`函数可以接受两个函数作为`resolved`状态和`rejected`状态的回调, 也就是说当`Promise`实例的状态改变时将会根据状态调用对应函数.
> 其中第二个参数(`rejected`状态的回调)是可选的, 不一定要提供, 在实际的开发中, `rejected`状态的回调使用`catch`函数更多一点, 稍后详细探讨.

### 执行流程

首先值得说一下得是, 我在网上查阅资料的时候, 看到一个的概念, 那就是`Promise`实例创建后将会立即执行, 所以我一开始推测下面代码的执行结果将是`1, 2, 3`. 因为第一行`Promise`实例创建, 那么将打印1, 然后执行`resolve()`, 改变`Promise`实例的状态, 然后执行下一行`promise.then`, 因为`promise`状态已经改变所以会打印2, 最后打印3.

<pre><code class="language-javascript">let promise = new Promise((resolve, reject) => {
  console.log('1');
  resolve();
});

promise.then(() => {
  console.log('2');
});

console.log('3');
</code></pre>
然而, 真实的运行结果为 `1, 3, 2`.
百思不得解, 请教JS大牛后恍然大悟.
原来, `Promise`实例创建后将会立即执行, 这句话没错, 我的问题在于`then`函数, then函数其实是个异步操作, 是一个微任务, 将跳过`then`函数, 执行下一行代码, 当完成当前`Event loop`之后再执行`then`函数内的操作.

微任务相关知识可参考: <a href='https://segmentfault.com/a/1190000014940904'>JS事件循环机制（event loop）之宏任务、微任务</a>

#### 异常捕捉
上文提到过, `then`函数可以接受两个函数作为`fulfilled`状态和`rejected`状态的回调, 但是大多数情况下更推荐使用`catch`函数. 现在我们聊聊`catch`函数.

`catch`函数实际上是方法是`then(null, rejection)`的别名, 也就是说下面梁行代码是等价的
<pre><code class="language-javascript">p.then((res) => console.log(res))
  .catch((err) => console.log(err));

p.then((res) => console.log(res))
  .then(null, (err) => console.log(err));
</code></pre>

但是为什么推荐使用`catch`呢?
`Promise`实例创建后, 当状态改变为`fulfilled`则调用then函数处理结果, 如果状态改变为`rejected`,则会调用`catch`方法处理异常, 并且`then`函数在处理结果的时候抛出异常, `catch`方法也能捕捉到, 这是因为`Promise`实例对象的错误具有“冒泡”性质, 会一直向后传递, 直到被捕获为止. 这个特点是then函数使用第二个参数处理异常不具备的. 

<pre><code class="language-javascript">p.then((res) => {
	// do something...	
}).catch((err) => {
	// 处理promise内部和then函数的异常
});
</code></pre>

#### 多个异步操作统一回调

`Promise.all()`用于包装多个`Promise`实例,最终返回一个新的`Promise`实例.
举个例子, 说下逻辑.

<pre><code class="language-javascript">const promises = new Promise.all([p1, p2, p3])
promises.then((resArr) => { 	// console.log(resArr)
}).catch((error) => {
	// console.log(error)
})
</code></pre>
`promises`实例的状态由`p1, p2, p3`这三个`Promise`实例决定,分为以下连个情况:

- `p1、p2、p3`的状态都变成`fulfilled`，`promises`的状态才会变成`fulfilled`, 然后将三个结果作为数组传递给回调参数.
- `p1、p2、p3`的状态有一个变成`rejected`, `promises`的状态就变成`rejected`, 并把这个实例的`rejected`的返回值传递给`promises`的回调函数.

值得注意的是, 如果作为参数的`Promise`实例拥有自己的`catch`方法, 那么当这个实例状态变为`rejected`时, 并不会触发`Promise.all()`的`catch`方法.

<pre><code class="language-javascript">const p1 = new Promise((resolve, reject) => {
  resolve('success');
})

const p2 = new Promise((resolve, reject) => {
  reject(new Error('error'))
})
.catch(e => e);

Promise.all([p1, p2])
.then(result => console.log(result))
.catch(e => console.log(e));
</code></pre>
打印结果为: 
`['success', Error: error..]`

为什么会这样呢? 分析一波如下
首先`p1`状态变为`fulfilled`, `p2`将抛出异常到`p2`的`catch`方法, 实际上`catch`方式会创建一个新的`Promise`实例, 也就是说`p2`将指向新的`Promise`实例, 所以状态变为`fulfilled`, 所以最后`Promise.all`中所有的`Promise`实例都为`fulfilled`, 最终调用`Promise.all()`的`then`方法.
假如`p2`实例没有`catch`方法, 那么不会创建新的`Promise`实例, `p2`的状态将为`rejected`, 则会触发`Promise.all()`的`catch`方法.

### 推荐阅读
<a href='http://es6.ruanyifeng.com/#README'>《ECMAScript 6 入门》</a>







